Workbook

Sheet Hoja1
A1: BUQUE | C1: A14
A2: MAREA | C2: 311
A3: INICIO | C3: 46204 | D3: PM
A4: FIN | C4: 46214 | D4: AM
C5: TOTAL | D5: MES 1 | E5: MES 2
A6: DIAS NAV | C6: =+C4-C3-1 -> 9 | D6: - | E6: 9
A7: DIAS PTO | C7: 2 | D7: . | E7: 2
A8: DIAS FDO | C8: 1 | D8: - | E8: 1
A9: USD billete | C9: 1460
A10: % REM | C10: 0.3
A11: % NO REM | C11: 0.7
C13: Valores producción fuera de convenio | J13: Producción final fuera de convenio | P13: Producción final AACPyPP - SOMU
A14: Clasif. | B14: Kgs.Netos | C14: Capitán | D14: J Máq | E14: 1º Ofic | F14: P Pesca | G14: G Máq | H14: Contra | I14: SOMU | J14: Capitán | K14: J Máq | L14: 1º Ofic | M14: P Pesca | N14: G Máq | O14: Contra | P14: 0.022 | Q14: 0.018 | R14: 0.01 | S14: 0.009 | T14: 0.0085
A15: L 1 | B15: 35676 | C15: 118.45 | D15: 103 | E15: 87.55 | F15: 194.89 | G15: 150.13688 | H15: 90.08 | I15: =0.82*5800 -> 4756 | J15: =+$B15*C15/1000*$C$9 -> 6169700.4 | K15: =+$B15*D15/1000*$C$9 -> 5364956.9 | L15: =+$B15*E15/1000*$C$9 -> 4560213.3 | M15: =+$B15*F15/1000*$C$9 -> 10151228 | N15: =+$B15*G15/1000*$C$9 -> 7820173.4 | O15: =+$B15*H15/1000*$C$9 -> 4691993.4 | P15: =($B15/1000*$I15*$C$9*P$14)*0.9 -> 4904966.5 | Q15: =($B15/1000*$I15*$C$9*Q$14)*0.9 -> 4013154.4 | R15: =($B15/1000*$I15*$C$9*R$14)*0.9 -> 2229530.2 | S15: =($B15/1000*$I15*$C$9*S$14)*0.9 -> 2006577.2 | T15: =($B15/1000*$I15*$C$9*T$14)*0.9 -> 1895100.7
A16: L 2 | B16: 34392 | C16: 87.92 | D16: 76.45 | E16: 64.98 | F16: 169.75 | G16: 130.76438 | H16: 78.46 | I16: =0.82*5500 -> 4510 | J16: =+$B16*C16/1000*$C$9 -> 4414667.2 | K16: =+$B16*D16/1000*$C$9 -> 3838731.9 | L16: =+$B16*E16/1000*$C$9 -> 3262796.6 | M16: =+$B16*F16/1000*$C$9 -> 8523541.3 | N16: =+$B16*G16/1000*$C$9 -> 6565982.6 | O16: =+$B16*H16/1000*$C$9 -> 3939658.6 | P16: =($B16/1000*$I16*$C$9*P$14)*0.9 -> 4483859.8 | Q16: =($B16/1000*$I16*$C$9*Q$14)*0.9 -> 3668612.5 | R16: =($B16/1000*$I16*$C$9*R$14)*0.9 -> 2038118.1 | S16: =($B16/1000*$I16*$C$9*S$14)*0.9 -> 1834306.3 | T16: =($B16/1000*$I16*$C$9*T$14)*0.9 -> 1732400.4
A17: L 3 | B17: 0 | C17: 71.44 | D17: 62.12 | E17: 52.8 | F17: 144.6 | G17: 111.39188 | H17: 66.84 | I17: =0.82*4500 -> 3690 | J17: =+$B17*C17/1000*$C$9 -> 0 | K17: =+$B17*D17/1000*$C$9 -> 0 | L17: =+$B17*E17/1000*$C$9 -> 0 | M17: =+$B17*F17/1000*$C$9 -> 0 | N17: =+$B17*G17/1000*$C$9 -> 0 | O17: =+$B17*H17/1000*$C$9 -> 0 | P17: =($B17/1000*$I17*$C$9*P$14)*0.9 -> 0 | Q17: =($B17/1000*$I17*$C$9*Q$14)*0.9 -> 0 | R17: =($B17/1000*$I17*$C$9*R$14)*0.9 -> 0 | S17: =($B17/1000*$I17*$C$9*S$14)*0.9 -> 0 | T17: =($B17/1000*$I17*$C$9*T$14)*0.9 -> 0
A18: C1 | B18: 21996 | C18: 117.27 | D18: 101.97 | E18: 86.68 | F18: 194.89 | G18: 150.13688 | H18: 90.08 | I18: =0.82*4500 -> 3690 | J18: =+$B18*C18/1000*$C$9 -> 3766027.5 | K18: =+$B18*D18/1000*$C$9 -> 3274680.9 | L18: =+$B18*E18/1000*$C$9 -> 2783655.4 | M18: =+$B18*F18/1000*$C$9 -> 6258728.6 | N18: =+$B18*G18/1000*$C$9 -> 4821519.6 | O18: =+$B18*H18/1000*$C$9 -> 2892843.5 | P18: =($B18/1000*$I18*$C$9*P$14)*0.9 -> 2346324.8 | Q18: =($B18/1000*$I18*$C$9*Q$14)*0.9 -> 1919720.3 | R18: =($B18/1000*$I18*$C$9*R$14)*0.9 -> 1066511.3 | S18: =($B18/1000*$I18*$C$9*S$14)*0.9 -> 959860.13 | T18: =($B18/1000*$I18*$C$9*T$14)*0.9 -> 906534.57
F19: 41.91 | M19: =+B20/1000*F19*C9 -> 5633267.3 | P19: =($B19/1000*$I19*$C$9*P$14)*0.9 -> 0 | Q19: =($B19/1000*$I19*$C$9*Q$14)*0.9 -> 0 | R19: =($B19/1000*$I19*$C$9*R$14)*0.9 -> 0 | S19: =($B19/1000*$I19*$C$9*S$14)*0.9 -> 0 | T19: =($B19/1000*$I19*$C$9*T$14)*0.9 -> 0
A20: TOTAL | B20: =SUM(B15:B19) -> 92064 | J20: =SUM(J15:J19) -> 14350395 | K20: =SUM(K15:K19) -> 12478370 | L20: =SUM(L15:L19) -> 10606665 | M20: =SUM(M15:M19) -> 30566765 | N20: =SUM(N15:N19) -> 19207676 | O20: =SUM(O15:O19) -> 11524496 | P20: =SUM(P14:P19) -> 11735151 | Q20: =SUM(Q14:Q19) -> 9601487.2 | R20: =SUM(R15:R19) -> 5334159.6 | S20: =SUM(S15:S19) -> 4800743.6 | T20: =SUM(T15:T19) -> 4534035.6
I21: PAGO MES 1 | R21: =R18/I18*I15 -> 1374614.5 | S21: =S18/I18*I15 -> 1237153.1 | T21: =T18/I18*I15 -> 1168422.3
G22: =+(11524495.5168+(92064/1000*0*1460))*0.3 -> 3457348.7 | K22: =+K20*0.15 -> 1871755.4 | M22: =41.91*92064*1460*0.3 -> 1.6899802e+09 | R22: Gratificación Producción Colas Marinería
I23: DIF | J23: =+J20-J21 -> 14350395 | K23: =+K20+K22-K21 -> 14350125 | M23: =+M20-M21 -> 30566765 | N23: =+N20-N21 -> 19207676 | O23: =+O20-O21 -> 11524496 | P23: =+P20-J21 -> 11735151 | Q23: =+Q20-L21 -> 9601487.2 | R23: =+R21-R18 -> 308103.25
J24: =+J25/30 -> 31710.4 | K24: =+K26/30 -> 91693.733 | O24: =+O20-O22 -> 11524496
B25: =+(11524495.5168)*0.3-85618.08-55016.239998-26161.08-165310.37-51370.848-0-0-0 -> 3073872 | E25: BAS NAV | F25: 3000000 | G25: 1500000 | H25: 3000000 | I25: 1500000 | J25: 951312 | K25: 951312 | L25: 895352 | M25: 839393 | N25: 783433 | O25: 783433 | R25: (($B18/1000*$I18*$C$9*R$14)*0,9) | T25: ((BASE_PROD_COLA/COEF_TANGONERO)*VALOR_C1*IF(PCT_NORM_TANG<>0,PCT_NORM_TANG,1)*TC_CERCANO*0,9)-PCT_PROD)VALOR_L1*IF(PCT_NORM_TANG<>0,PCT_NORM_TANG,1)-BASE_PROD_COLA/COEF_TANGONERO)
B26: =+F26/30 -> 267666.67 | E26: BAS PTO | F26: =5500*$C$9 -> 8030000 | G26: =3600*C9 -> 5256000 | H26: =5500*$C$9 -> 8030000 | I26: =3600*C9 -> 5256000 | J26: 2750812 | K26: 2750812 | L26: 2589000 | M26: 2427187 | N26: 2265375 | O26: 2265375 | P26: =+K25/30 -> 31710.4 | Q26: =+O23*0.3 -> 3457348.7 | R26: Producción Colas tn * Valor SOMU * TC * Coef producción/Valor colas SOMU* Valor entero SOMU
A27: Concepto | E27: Un | F27: Capitán | G27: J Máq | H27: P Pesca | I27: G Máq | J27: Cont Esp | K27: C y C | L27: Mozo | M27: Eng y M Cbt | N27: M Pta | O27: Bod / Tun | Q27: =-SUM(J29:J43) -> -1982932.8
F28: 4291 | G28: 2744 | H28: 1541 | I28: 406 | J28: 1588-3788 | K28: 4700-2792 | L28: 4351 | S28: (319.953,37608/0,3/4500*IF(82%<>0,82%,1)*5800*IF(82%<>0,82%,1)-319.953,37608)*0,3
A29: Sueldo navegación | E29: 9 | F29: =+F$25/30*$E29*$C$10 -> 270000 | G29: =+G$25/30*$E29*$C$10 -> 135000 | H29: =+H$25/30*$E29*$C$10 -> 270000 | I29: =+I$25/30*$E29*$C$10 -> 135000 | J29: =+J$25/30*$E29*$C$10 -> 85618.08 | K29: =+K$25/30*$E29*$C$10 -> 85618.08 | L29: =+L$25/30*$E29*$C$10 -> 80581.68 | M29: =+M$25/30*$E29*$C$10 -> 75545.37 | ... O29: =+O$25/30*$E29*$C$10 -> 70508.97 | P29: 70508.97 | Q29: =+N29-P29 -> 0
A30: Sueldo puerto | E30: 2 | F30: =+F$26/30*$E30*$C$10 -> 160600 | G30: =+G$26/30*$E30*$C$10 -> 105120 | H30: =+H$26/30*$E30*$C$10 -> 160600 | I30: =+I$26/30*$E30*$C$10 -> 105120 | J30: =+J$26/30*$E30*$C$10 -> 55016.24 | K30: =+K$26/30*$E30*$C$10 -> 55016.24 | L30: =+L$26/30*$E30*$C$10 -> 51780 | M30: =+M$26/30*$E30*$C$10 -> 48543.74 | ... O30: =+O$26/30*$E30*$C$10 -> 45307.5 | P30: 45307.5 | Q30: =+N30-P30 -> 0 | S30: =(+B18/1000*I18*C9*R14)*0.9/I18*I15 -> 1374614.5
A31: Antigüedad | E31: 0.25 | F31: =F$25/30*($E29+$E30)*14/100*$C$10 -> 46200 | G31: =G$25/30*($E29+$E30)*$E31*$C$10 -> 41250 | H31: =H$25/30*($E29+$E30)*$E31*$C$10 -> 82500 | I31: =I$25/30*($E29+$E30)*$E31*$C$10 -> 41250 | J31: =J$25/30*($E29+$E30)*$E31*$C$10 -> 26161.08 | K31: =K$25/30*($E29+$E30)*$E31*$C$10 -> 26161.08 | L31: =L$25/30*($E29+$E30)*$E31*$C$10 -> 24622.18 | M31: =M$25/30*($E29+$E30)*$E31*$C$10 -> 23083.307 | N31: =N$25/30*($E29+$E30)*$E31*$C$10 -> 21544.407 | O31: =O$25/30*($E29+$E30)*$E31*$C$10 -> 21544.407 | P31: 15511.97 | Q31: =+N31-P31 -> 6032.4375 | S31: =(+S30-R18)*C10 -> 92430.975
A32: Adicional Art 23 - 33 | E32: 0.6 | F32: =+F29*$E32 -> 162000 | G32: =+G29*$E32 -> 81000 | H32: =+H29*$E32 -> 162000 | I32: =+I29*$E32 -> 81000 | J32: =+J29*$E32 -> 51370.848 | K32: =+K29*$E32 -> 51370.848 | L32: =+L29*$E32 -> 48349.008 | M32: =+M29*$E32 -> 45327.222 | ... O32: =+O29*$E32 -> 42305.382 | P32: 42305.38 | Q32: =+N32-P32 -> 0.002 | R32: CATEGORIA SUPERIOR PTA - CBTA
A33: Incentivo producción | E33: =+E29 -> 9 | F33: 0 | G33: 0 | H33: 0 | I33: 0 | J33: =50/70*85*$E33*$C$10 -> 163.92857 | K33: =50/70*85*$E33*$C$10 -> 163.92857 | L33: =50/70*80*$E33*$C$10 -> 154.28571 | M33: =50/70*75*$E33*$C$10 -> 144.64286 | N33: =50*$E33*$C$10 -> 135 | O33: =50*$E33*$C$10 -> 135 | P33: 135 | Q33: =+N33-P33 -> 0
A34: Plus carga completa | E34: 1928 | F34: 0 | G34: 0 | H34: 0 | I34: 0 | J34: =+$B$20/1000*$E34*$C$10 -> 53249.818 | K34: =+$B$20/1000*$E34*$C$10 -> 53249.818 | L34: =+$B$20/1000*$E34*$C$10 -> 53249.818 | M34: =+$B$20/1000*$E34*$C$10 -> 53249.818 | N34: =+$B$20/1000*$E34*$C$10 -> 53249.818 | O34: =+$B$20/1000*$E34*$C$10 -> 53249.818 | P34: 53247.5 | Q34: =+N34-P34 -> 2.3176
A35: Premio adicional especial producción | F35: =+(P23*$C$10)-F29-F30-F31-F32-F42 -> 2823672.6 | G35: 0 | H35: =+(P23*$C$10)-H29-H30-H31-H32-H42 -> 2784072.6 | I35: 0 | J35: 0 | K35: 0 | L35: 0 | M35: 0 | N35: 0 | O35: 0 | Q35: =+N35-P35 -> 0 | S35: =+R15/0.3 -> 7431767.5
A36: Langostino entero 1 | F36: 0 | G36: 0 | H36: 0 | I36: 0 | J36: =+$R15*$C$10 -> 668859.07 | K36: =+$R15*$C$10 -> 668859.07 | L36: =+$S15*$C$10 -> 601973.16 | M36: =+$S15*$C$10 -> 601973.16 | N36: =+$T15*$C$10 -> 568530.21 | O36: =+$T15*$C$10 -> 568530.21 | P36: 568530.21 | Q36: =+N36-P36 -> 0.00013920013 | R36: Descarga en tn*Precio SOMU*82%*TC*porcentaje producción categoría *0,9*porcentaje remunerativo
A37: Langostino entero 2 | F37: 0 | G37: 0 | H37: 0 | I37: 0 | J37: =+$R16*$C$10 -> 611435.42 | K37: =+$R16*$C$10 -> 611435.42 | L37: =+$S16*$C$10 -> 550291.88 | M37: =+$S16*$C$10 -> 550291.88 | N37: =+$T16*$C$10 -> 519720.11 | O37: =+$T16*$C$10 -> 519720.11 | P37: 519720.11 | Q37: =+N37-P37 -> -0.0024559999 | R37: =($B15/1000*$I15*$C$9*R$14)*0.9 -> 2229530.2 | S37: ($B15/1000*$I15*$C$9*R$14)*0,9
A38: Langostino entero 3 | F38: 0 | G38: 0 | H38: 0 | I38: 0 | J38: =+$R17*$C$10 -> 0 | K38: =+$R17*$C$10 -> 0 | L38: =+$S17*$C$10 -> 0 | M38: =+$S17*$C$10 -> 0 | N38: =+$T17*$C$10 -> 0 | O38: =+$T17*$C$10 -> 0 | Q38: =+N38-P38 -> 0 | R38: =+$R15*$C$10 -> 668859.07 | S38: $R15*$C$10
A39: Langostino cola 1 | F39: 0 | G39: 0 | H39: 0 | I39: 0 | J39: =+$R18*$C$10 -> 319953.38 | K39: =+$R18*$C$10 -> 319953.38 | L39: =+$S18*$C$10 -> 287958.04 | M39: =+$S18*$C$10 -> 287958.04 | N39: =+$T18*$C$10 -> 271960.37 | O39: =+$T18*$C$10 -> 271960.37 | P39: 271960.37 | Q39: =+N39-P39 -> -0.00033200003
A40: Gratificación producción colas | F40: 0 | G40: 0 | H40: 0 | I40: 0 | J40: =+($R$21-$R$18)*$C$10 -> 92430.975 | K40: =+($R$21-$R$18)*$C$10 -> 92430.975 | L40: =+($S$21-$S$18)*$C$10 -> 83187.878 | M40: =+($S$21-$S$18)*$C$10 -> 83187.878 | N40: =+($T$21-$T$18)*$C$10 -> 78566.329 | O40: =+($T$21-$T$18)*$C$10 -> 78566.329 | P40: 78568.61 | Q40: =+N40-P40 -> -2.2809848
A41: Absorción SOMU | F41: 0 | G41: 0 | H41: 0 | I41: 0 | J41: =(J29+J34)*-1 -> -138867.9 | K41: =(K29+K34)*-1 -> -138867.9 | L41: =(L29+L34)*-1 -> -133831.5 | M41: =(M29+M34)*-1 -> -128795.19 | N41: =(N29+N34)*-1 -> -123758.79 | O41: =(O29+O34)*-1 -> -123758.79 | P41: -123758.78 | Q41: =+N41-P41 -> -0.0076
...

Sheet Hoja5
A1: Orden Cálculo | B1: Cód. Concepto | C1: Nombre Impresión | D1: Tipo Concepto | E1: Cantidad | F1: Unidad | G1: Base Cálculo | H1: Importe | I1: Vigencia Concepto | J1: Fórmula Aplicada | K1: Fórmula con Valores
A2: 15 | B2: 1013 | C2: Sueldo de navegacion | D2: Haber Remunerativo | E2: 9 | F2: DIA | G2: 0 | H2: 85617 | I2: 44938 | J2: round(DIAS_PROYECTO * PRECIO_NAV* COEF_TANGONERO,0.0001) | K2: ROUND(9 * 31710* 0,3,0.0001)
A3: 20 | B3: 1803 | C3: Horas extras 50% | D3: Haber Remunerativo | E3: 8 | F3: HORA | G3: 2432.33 | H3: 19458.64 | I3: 44938
A4: 25 | B4: 1813 | C4: Horas extras 100% | D4: Haber Remunerativo | E4: 3 | F4: HORA | G4: 3243.11 | H4: 9729.33 | I4: 44938
A5: 50 | B5: 1053 | C5: Antiguedad | D5: Haber Remunerativo | E5: 0 | G5: 0 | H5: 26160.75 | I5: 44938 | J5: if(DIAS_ENROLAMIENTO<>0,round((DIAS_PROYECTO +DIAS_PUERTO)*PRECIO_NAV* PCT_ANTIG*COEF_TANGONERO,0.0001),round(BASICO*ANIOS_ANT* PCT_ANTIG,0.0001)) | K5: IF(22<>0,ROUND((9 +2)*31710* 25%*0,3,0.0001),ROUND(0*9* 25%,0.0001))
A6: 80 | B6: 1083 | C6: Sueldo de puerto | D6: Haber Remunerativo | E6: 2 | F6: DIA | G6: 0 | H6: 55016.4 | I6: 44938 | J6: DIAS_PUERTO*PRECIO_PUERTO*COEF_TANGONERO | K6: 2*91694*0,3
A7: 141 | B7: 2403 | C7: Produccion langostino entero 1 | D7: Haber Remunerativo | E7: 35676 | F7: KN | G7: 0 | H7: 668859.07 | I7: 44938 | J7: (PROD_KN_L1 / 1000 * VALOR_L1_SOMU*PCT_NORM_TANG * IF(PCT_PROD<>0,PCT_PROD,1)/100 * 0,9 * TC_CERCANO)*COEF_TANGONERO | K7: (35676 / 1000 * 5800*82% * IF(100%<>0,100%,1)/100 * 0,9 * 1460)*0,3
A8: 142 | B8: 2413 | C8: Produccion langostino entero 2 | D8: Haber Remunerativo | E8: 34392 | F8: KN | G8: 0 | H8: 611435.42 | I8: 44938 | J8: (PROD_KN_L2 / 1000 * VALOR_L2_SOMU*PCT_NORM_TANG * IF(PCT_PROD<>0,PCT_PROD,1)/100 * 0,9 * TC_CERCANO)*COEF_TANGONERO | K8: (34392 / 1000 * 5500*82% * IF(100%<>0,100%,1)/100 * 0,9 * 1460)*0,3
A9: 147 | B9: 2463 | C9: Produccion langostino cola 1 | D9: Haber Remunerativo | E9: 21996 | F9: KN | G9: 0 | H9: 319953.38 | I9: 44938 | J9: (PROD_KN_C1 / 1000 * VALOR_C1_SOMU*PCT_NORM_TANG * IF(PCT_PROD<>0,PCT_PROD,1)/100 * 0,9 * TC_CERCANO)*COEF_TANGONERO | K9: (21996 / 1000 * 4500*82% * IF(100%<>0,100%,1)/100 * 0,9 * 1460)*0,3
A10: 151 | B10: 1093 | C10: Gratificacion produccion langostino colas | D10: Haber Remunerativo | E10: 0 | G10: 0 | H10: 92430.98 | I10: 44938 | J10: (((BASE_PROD_COLA/COEF_TANGONERO)/VALOR_C1_SOMU*VALOR_L1_SOMU)-(BASE_PROD_COLA/COEF_TANGONERO))*COEF_TANGONERO | K10: (((319.953,37608/0,3)/4500*5800)-(319.953,37608/0,3))*0,3
A11: 155 | B11: 1543 | C11: Adicional articulo 33 | D11: Haber Remunerativo | E11: 0 | G11: 0 | H11: 51370.2 | I11: 44938 | J11: round(@1013*PCT_33,0.0001) | K11: ROUND(85617*60%,0.0001)
A12: 157 | B12: 1023 | C12: Sueldo de feriado | D12: Haber Remunerativo | E12: 1 | F12: DIA | G12: 0 | H12: 165310.2 | I12: 44938 | J12: round(BASE_FERIADO/(DIAS_PROYECTO+DIAS_PUERTO),0.01)*DIAS_FERIADOS | K12: ROUND(1.818.412,217472/(9+2),0.01)*1
A13: 160 | B13: 1547 | C13: Incentivo a la produccion | D13: Haber Remunerativo | E13: 0 | G13: 0 | H13: 163.93 | I13: 44938 | J13: round(50/70*85*DIAS_PROYECTO * COEF_TANGONERO,0.0001) | K13: ROUND(50/70*85*9 * 0,3,0.0001)
A14: 205 | B14: 1174 | C14: Adicional bodega remunerativo | D14: Haber Remunerativo | E14: 0 | G14: 0 | H14: 53249.82 | I14: 44938 | J14: PROD_KN_MAREA/1000*VAL_CARG_COMP*COEF_TANGONERO | K14: 92064/1000*1928*0,3
A15: 665 | B15: 4813 | C15: Anticipo de llegada | D15: Descuento Empleado | E15: 0 | G15: 0 | H15: -250000 | I15: 44938
A16: 400 | B16: 4415 | C16: Absorcion articulo 36 CCT SOMU-CAPECA | D16: Deducción Remunerativa | E16: 0 | G16: 0 | H16: -138866.82 | I16: 44938 | J16: BASE_ABS_SOMU*-1 | K16: 138.866,8176*-1
B18: Sueldo navegación | C18: 9.00 | D18: 85618.08 | E18: =+H2 -> 85617 | F18: =+D18-E18 -> 1.08
B19: Sueldo puerto | C19: 2.00 | D19: 55016.24 | E19: =+H6 -> 55016.4 | F19: =+D19-E19 -> -0.16
B20: Adicional Art. 33 | D20: 51370.85 | E20: =+H11 -> 51370.2 | F20: =+D20-E20 -> 0.65
B21: Horas extras 50 * | C21: 8 | D21: 19458.65 | E21: =+H3 -> 19458.64 | F21: =+D21-E21 -> 0.01
B22: Horas extras 100 * | C22: 3 | D22: 9729.33 | E22: =+H4 -> 9729.33 | F22: =+D22-E22 -> 0
B23: Absorción Art. 36 CCT 729/2015 | D23: -29187.98 | F23: =+D23-E23 -> -29187.98
B24: Antiguedad | C24: 19.00 | D24: 26161.08 | E24: =+H5 -> 26160.75 | F24: =+D24-E24 -> 0.33
B25: Plus carga completa | D25: 53247.5 | E25: =+H14 -> 53249.82 | F25: =+D25-E25 -> -2.32
B26: Incentivo a la producción | C26: 9.00 | D26: 163.93 | E26: =+H13 -> 163.93 | F26: =+D26-E26 -> 0
B27: Producción langostino entero 1 35.68 | D27: 668858.85 | E27: =+H7 -> 668859.07 | F27: =+D27-E27 -> -0.22
B28: Producción langostino entero 2 34.39 | D28: 611435.74 | E28: =+H8 -> 611435.42 | F28: =+D28-E28 -> 0.32
B29: Producción langostino cola 1 | C29: 22.00 | D29: 319952.43 | E29: =+H9 -> 319953.38 | F29: =+D29-E29 -> -0.95
B30: Absorción acuerdo SOMU-CAPECA | D30: -138865.58 | E30: =+H16 -> -138866.82 | F30: =+D30-E30 -> 1.24
B31: Sueldo día feriado | C31: 1.00 | D31: 157541.74 | E31: =+H12 -> 165310.2 | F31: =+D31-E31 -> -7768.46
B32: Gratificación prod lang colas | D32: 92431.78 | E32: =+H10 -> 92430.98 | F32: =+D32-E32 -> 0.8
B33: A cuenta futuros aumentos | D33: 1474415.9
D34: =SUM(D18:D33) -> 3457348.5 | E34: =SUM(E18:E33) -> 2019888.3
E35: =+E34+D33 -> 3494304.2 | F35: =+E35-D34 -> 36955.66

Sheet Hoja2
A1: No. Empleado | B1: Nombre Empleado | C1: No. Proyecto | D1: Buque | E1: Marea | F1: Cód. Convenio | G1: Cód. Categoría | H1: Rol en Proyecto | I1: Fecha Alta Asignación | J1: Fecha Baja | K1: Zona Desfavorable
A2: 406 | B2: CARLOS ESTEBAN | C2: PP-114-000311 | D2: 114 | E2: 311 | F2: 175/75 | G2: OF02 | I2: 46204 | K2: 0
A3: 1541 | B3: SERGIO JULIAN | C3: PP-114-000311 | D3: 114 | E3: 311 | F3: 175/75 | G3: OF01 | I3: 46204 | K3: 0
A4: 1588 | B4: CARLOS DAMIAN | C4: PP-114-000311 | D4: 114 | E4: 311 | F4: 729/15 | G4: MR01 | I4: 46204 | K4: 0
A5: 2262 | B5: OSCAR ANTENOR | C5: PP-114-000311 | D5: 114 | E5: 311 | F5: 729/15 | G5: MR05 | I5: 46204 | K5: 0
A6: 2320 | B6: MARCOS CESAR | C6: PP-114-000311 | D6: 114 | E6: 311 | F6: 729/15 | G6: MR08 | I6: 46204 | K6: 0
A7: 2470 | B7: RAMON ALEJANDRO | C7: PP-114-000311 | D7: 114 | E7: 311 | F7: 729/15 | G7: MR05 | I7: 46204 | K7: 0
A8: 2668 | B8: PEDRO | C8: PP-114-000311 | D8: 114 | E8: 311 | F8: 729/15 | G8: MR05 | I8: 46204 | K8: 0
A9: 2741 | B9: EDUARDO ANTONIO | C9: PP-114-000311 | D9: 114 | E9: 311 | F9: 729/15 | G9: MR05 | I9: 46204 | K9: 0
A10: 2742 | B10: CRISTIAN ORLANDO | C10: PP-114-000311 | D10: 114 | E10: 311 | F10: 729/15 | G10: MR05 | I10: 46204 | K10: 0
A11: 2744 | B11: MARIANO ANGEL | C11: PP-114-000311 | D11: 114 | E11: 311 | F11: 175/75 | G11: OF02 | I11: 46204 | K11: 0
A12: 2745 | B12: JULIO JESUS | C12: PP-114-000311 | D12: 114 | E12: 311 | F12: 729/15 | G12: MR05 | I12: 46204 | K12: 0
A13: 2792 | B13: RUBEN DARIO | C13: PP-114-000311 | D13: 114 | E13: 311 | F13: 729/15 | G13: MR02 | I13: 46204 | K13: 0
... A31: 4848 | B31: DANIEL ORLANDO | C31: PP-114-000311 | D31: 114 | E31: 311 | F31: 729/15 | G31: MR08 | I31: 46204 | K31: 0

Sheet Hoja3
A1: Orden Cálculo | B1: Cód. Concepto | C1: Nombre Impresión | D1: Tipo Concepto | E1: Cantidad | F1: Unidad | G1: Base Cálculo | H1: Importe | I1: ARB | J1: Dif | K1: Vigencia Concepto | L1: Fórmula Aplicada | M1: Fórmula con Valores
A2: 15 | B2: 1013 | C2: Sueldo de navegacion | D2: Haber Remunerativo | E2: 9 | F2: DIA | G2: 0 | H2: 85617 | I2: =+Hoja4!C2 -> 85618.08 | J2: =+H2-I2 -> -1.08 | K2: 44938 | L2: round(DIAS_PROYECTO * PRECIO_NAV* COEF_TANGONERO,0.0001) | M2: ROUND(9 * 31710* 0,3,0.0001)
A3: 50 | B3: 1053 | C3: Antiguedad | D3: Haber Remunerativo | E3: 0 | G3: 0 | H3: 26160.75 | I3: =+Hoja4!C8 -> 26161.08 | J3: =+H3-I3 -> -0.33 | K3: 44938 | L3: round(DIAS_ENROLAMIENTO*PRECIO_NAV* PCT_ANTIG*COEF_TANGONERO,0.0001) | M3: ROUND(11*31710* 25%*0,3,0.0001)
A4: 80 | B4: 1083 | C4: Sueldo de puerto | D4: Haber Remunerativo | E4: 2 | F4: DIA | G4: 0 | H4: 55016.4 | I4: =+Hoja4!C3 -> 55016.24 | J4: =+H4-I4 -> 0.16 | K4: 44938 | L4: DIAS_PUERTO*PRECIO_PUERTO*COEF_TANGONERO | M4: 2*91694*0,3
A5: 141 | B5: 2403 | C5: Produccion langostino entero 1 | D5: Haber Remunerativo | E5: 35676 | F5: KN | G5: 0 | H5: 668859.07 | I5: =+Hoja4!C11 -> 668858.85 | J5: =+H5-I5 -> 0.22 | K5: 44938 | L5: (PROD_KN_L1 / 1000 * VALOR_L1*PCT_NORM_TANG * IF(PCT_PROD<>0,PCT_PROD,1)/100 * 0,9 * TC_CERCANO)*COEF_TANGONERO | M5: (35676 / 1000 * 5800*82% * IF(100%<>0,100%,1)/100 * 0,9 * 1460)*0,3
A6: 142 | B6: 2413 | C6: Produccion langostino entero 2 | D6: Haber Remunerativo | E6: 34392 | F6: KN | G6: 0 | H6: 611435.42 | I6: =+Hoja4!C12 -> 611435.74 | J6: =+H6-I6 -> -0.32 | K6: 44938 | L6: (PROD_KN_L2 / 1000 * VALOR_L2*PCT_NORM_TANG * IF(PCT_PROD<>0,PCT_PROD,1)/100 * 0,9 * TC_CERCANO)*COEF_TANGONERO | M6: (34392 / 1000 * 5500*82% * IF(100%<>0,100%,1)/100 * 0,9 * 1460)*0,3
A7: 147 | B7: 2463 | C7: Produccion langostino cola 1 | D7: Haber Remunerativo | E7: 21996 | F7: KN | G7: 0 | H7: 319953.38 | I7: =+Hoja4!C13 -> 319952.43 | J7: =+H7-I7 -> 0.95 | K7: 44938 | L7: (PROD_KN_C1 / 1000 * VALOR_C1*PCT_NORM_TANG * IF(PCT_PROD<>0,PCT_PROD,1)/100 * 0,9 * TC_CERCANO)*COEF_TANGONERO | M7: (21996 / 1000 * 4500*82% * IF(100%<>0,100%,1)/100 * 0,9 * 1460)*0,3
A8: 151 | B8: 1093 | C8: Gratificacion produccion langostino colas | D8: Haber Remunerativo | E8: 0 | G8: 0 | H8: 92430.98 | I8: =+Hoja4!C16 -> 92431.78 | J8: =+H8-I8 -> -0.8 | K8: 44938 | L8: (((BASE_PROD_COLA/COEF_TANGONERO)/VALOR_C1*VALOR_L1)-(BASE_PROD_COLA/COEF_TANGONERO))*COEF_TANGONERO | M8: (((319.953,37608/0,3)/4500*5800)-(319.953,37608/0,3))*0,3
A9: 155 | B9: 1543 | C9: Adicional articulo 33 | D9: Haber Remunerativo | E9: 0 | G9: 0 | H9: 51370.2 | I9: =+Hoja4!C4 -> 51370.85 | J9: =+H9-I9 -> -0.65 | K9: 44938 | L9: round(DIAS_PROYECTO * PRECIO_NAV*PCT_33* COEF_TANGONERO,0.0001) | M9: ROUND(9 * 31710*60%* 0,3,0.0001)
A10: 160 | B10: 1547 | C10: Incentivo a la produccion | D10: Haber Remunerativo | E10: 0 | G10: 0 | H10: 163.93 | I10: =+Hoja4!C10 -> 163.93 | J10: =+H10-I10 -> 0 | K10: 44938 | L10: round(50/70*85*DIAS_PROYECTO * COEF_TANGONERO,0.0001) | M10: ROUND(50/70*85*9 * 0,3,0.0001)
A11: 205 | B11: 1174 | C11: Adicional bodega remunerativo | D11: Haber Remunerativo | E11: 0 | G11: 0 | H11: 53249.82 | I11: =+Hoja4!C9 -> 53247.5 | J11: =+H11-I11 -> 2.32 | K11: 44938 | L11: PROD_KN_MAREA/1000*VAL_CARG_COMP*COEF_TANGONERO | M11: 92064/1000*1928*0,3
A12: 400 | B12: 4415 | C12: Absorcion articulo 36 CCT SOMU-CAPECA | D12: Deducción Remunerativa | E12: 0 | G12: 0 | H12: -138866.82 | I12: =+Hoja4!C14 -> -138865.58 | J12: =+H12-I12 -> -1.24 | K12: 44938 | L12: BASE_ABS_SOMU*-1 | M12: 138.866,8176*-1
A13: 700 | B13: 8522 | C13: Cuota sindical | D13: Descuento Empleado | E13: 0 | G13: 0 | H13: 85721.24 | J13: =+H13-I13 -> 85721.24 | K13: 44938 | L13: round(BASE_SINDICAL * PCT_CUOTA_SIND,0.0001) | M13: ROUND(2.143.031,067984 * 4%,0.0001)
A14: 900 | B14: 6000 | C14: Jubilacion | D14: Seguridad Social | E14: 0 | G14: 0 | H14: 235733.42 | I14: =+Hoja4!D19 -> 380308.34 | J14: =+H14-I14 -> -144574.92 | K14: 44938 | L14: round(MIN(BASE_SS,TOPE_SIPA)*PCT_JUB,0.0001) | M14: ROUND(MIN(2.143.031,067984,4.414.652,38)*11%,0.0001)
A15: 906 | B15: 6010 | C15: Ley 19032 | D15: Seguridad Social | E15: 0 | G15: 0 | H15: 64290.93 | J15: =+H15-I15 -> 64290.93 | K15: 44938 | L15: round(MIN(BASE_SS,TOPE_SIPA)*PCT_19032,0.0001) | M15: ROUND(MIN(2.143.031,067984,4.414.652,38)*3%,0.0001)
A16: 912 | B16: 6030 | C16: Obra social | D16: Seguridad Social | E16: 0 | G16: 0 | H16: 64290.93 | J16: =+H16-I16 -> 64290.93 | K16: 44938 | L16: round(MIN(BASE_OS,TOPE_SIPA_OS)*PCT_OS,0.0001) | M16: ROUND(MIN(2.143.031,067984,4.414.652,38)*3%,0.0001)
A17: 930 | B17: 7000 | C17: Contrib. patronal jubilacion | D17: Contribución Patronal | E17: 0 | G17: 0 | H17: 230050.15 | J17: =+H17-I17 -> 230050.15 | K17: 44938 | L17: round(MAX(0,BASE_IG4+BASE_EXT_IG4-DED_CONT_PATR)*PCT_CONT_JUB,0.0001) | M17: ROUND(MAX(0,2.143.031,067984+0-7.003,68)*10,77%,0.0001)
A18: 934 | B18: 7010 | C18: Contrib. patronal ley 19032 | D18: Contribución Patronal | E18: 0 | G18: 0 | H18: 33962.84 | J18: =+H18-I18 -> 33962.84 | K18: 44938 | L18: round(MAX(0,BASE_IG4+BASE_EXT_IG4-DED_CONT_PATR )*PCT_CONT_19032,0.0001) | M18: ROUND(MAX(0,2.143.031,067984+0-7.003,68 )*1,59%,0.0001)
A19: 936 | B19: 7030 | C19: Obra Social | D19: Contribución Patronal | E19: 0 | G19: 0 | H19: 128581.86 | J19: =+H19-I19 -> 128581.86 | K19: 44938 | L19: round(MAX(0,BASE_IG4+BASE_EXT_IG4)*PCT_CONT_23660,0.0001) | M19: ROUND(MAX(0,2.143.031,067984+0)*6%,0.0001)
A20: 938 | B20: 7050 | C20: ART | D20: Contribución Patronal | E20: 0 | G20: 0 | H20: 160186.3 | J20: =+H20-I20 -> 160186.3 | K20: 44938 | L20: round(BASE_LRT*PCT_ART+VALOR_ART_FIJO,0.0001) | M20: ROUND(2.143.031,067984*7,4%+1602,0.0001)
A21: 939 | B21: 7060 | C21: Asignaciones Familiares | D21: Contribución Patronal | E21: 0 | G21: 0 | H21: 100393.29 | J21: =+H21-I21 -> 100393.29 | K21: 46023 | L21: round(MAX(0,BASE_IG4+BASE_EXT_IG4-DED_CONT_PATR)*PCT_ASIG_FAMI,0.0001) | M21: ROUND(MAX(0,2.143.031,067984+0-7.003,68)*4,7%,0.0001)
A22: 940 | B22: 7070 | C22: Fondo Nacional de Empleo | D22: Contribución Patronal | E22: 0 | G22: 0 | H22: 20078.66 | J22: =+H22-I22 -> 20078.66 | K22: 46023 | L22: round(MAX(0,BASE_IG4+BASE_EXT_IG4-DED_CONT_PATR)*PCT_FNE,0.0001) | M22: ROUND(MAX(0,2.143.031,067984+0-7.003,68)*0,94%,0.0001)

Sheet Hoja4
A1: Concepto | B1: Unidades | C1: Haberes C/D. | D1: Descuentos | E1: Haberes S/D
A2: Sueldo navegación | B2: 9.00 | C2: 85618.08
A3: Sueldo puerto | B3: 2.00 | C3: 55016.24
A4: Adicional Art. | B4: 33 | C4: 51370.85
A5: Horas extras 50% | B5: 8.00 | C5: 19458.65
A6: Horas extras 100% | B6: 3.00 | C6: 9729.33
A7: Absorción Art.36 CCT 729/2015 | C7: -29187.98
A8: Antiguedad | B8: 19.00 | C8: 26161.08
A9: Plus carga completa | C9: 53247.5
A10: Incentivo a la producción | B10: 9.00 | C10: 163.93
A11: Producción L1 | B11: 35.68 | C11: 668858.85
A12: Producción L2 | B12: 34.39 | C12: 611435.74
A13: Producción C1 | B13: 22.00 | C13: 319952.43
A14: Absorción acuerdo SOMU-CAPECA | C14: -138865.58
A15: Sueldo día feriado | B15: 1.00 | C15: 157541.74
A16: Gratificación prod. Lang. Colas | C16: 92431.78
A17: A cuenta futuros aumentos | C17: 1474415.9
A18: Ley 19032 | B18: 3.00 | D18: 103720.46
A19: Jubilación | B19: 11.00 | D19: 380308.34
A20: OSPM | B20: 3.00 | D20: 135287.02
A21: SOMU | B21: 4.00 | D21: 460979.81
A22: Anticipo llegada | D22: 250000
A23: Impuesto a las ganancias | D23: 2069759.4
A24: Acuerdo sindical Dto.633/18 | B24: sindical | E24: 8067146.6
A25: Redondeo | E25: 0.85
C26: =SUM(C2:C24) -> 3457348.5 | D26: =SUM(D2:D24) -> 3400055 | E26: =SUM(E24:E25) -> 8067147.4
E27: =+C26-D26+E26 -> 8124441
